#VRML_SIM R2025a utf8

EXTERNPROTO "Gate.proto"

PROTO RampStairsSeesaw [
  field SFVec3f    translation       0 0 0
  field SFRotation rotation          0 0 1 0
  field SFColor    ballColor         1 0.333333 0
  field SFColor    edgeColor         0.54902 0.54902 0.54902
  field SFColor    holeColor         0.701961 0.701961 0.521569
  field SFColor    lineColor         1 1 1
  field SFColor    surfaceColor      0.262745 0.262745 0.262745
  field SFFloat    seesawAngle       -0.001
]
{
Solid {
  name "solidRampStairsSeesaw"
  translation IS translation
  rotation IS rotation
  children [
    DEF base Shape {
      appearance DEF rampbase_app PBRAppearance {
        baseColor IS edgeColor
        roughness 1
        metalness 0
      }
      geometry Mesh {
        url [
          "RampStairsSeesaw_RampStairs.dae"
        ]
        materialIndex 0
      }
    }
    DEF line Shape {
      appearance DEF rampline_app PBRAppearance {
        baseColor IS lineColor
        roughness 1
        metalness 0
      }
      geometry Mesh {
        url [
          "RampStairsSeesaw_RampStairs.dae"
        ]
        materialIndex 1
      }
    }
    DEF surface Shape {
      appearance DEF rampsurface_app PBRAppearance {
        baseColor IS surfaceColor
        roughness 1
        metalness 0
      }
      geometry Mesh {
        url [
          "RampStairsSeesaw_RampStairs.dae"
        ]
        materialIndex 3
      }
    }
    DEF hole Shape {
      appearance PBRAppearance {
        baseColor IS holeColor
        roughness 1
        metalness 0
      }
      geometry Mesh {
        url [
          "RampStairsSeesaw_RampStairs.dae"
        ]
        materialIndex 2
      }
    }
    Gate {
      translation -0.905 1.07 0.37
      has_foot FALSE
    }
    Gate {
      translation 0.32 -0.825 0.44
      rotation 0 0 1 1.57
      name "Gate(1)"
      has_foot FALSE
    }
    Gate {
      translation 1.14 -0.825 0.22
      rotation 0 0 1 1.57
      name "Gate(3)"
      has_foot FALSE
    }
    Gate {
      translation 0.32 -1.425 0.46
      rotation 0 0 1 1.57
      name "Gate(2)"
      has_foot FALSE
    }
    Solid {
      children [
        HingeJoint {
          jointParameters HingeJointParameters {
            position IS seesawAngle
            axis 0 1 0
            anchor 0.6 0.6 0.372612
            minStop -0.001
            maxStop 0.423
          }
          endPoint Solid {
            translation 0.0003729119378975687 3.2085445411667024e-14 -0.0005998135940031291
            rotation 0 -1 0 0.0009999999998284146
            children [
              Shape {
                appearance USE rampsurface_app
                geometry DEF seesawmesh Mesh {
                  url [
                    "RampStairsSeesaw_Seesaw.dae"
                  ]
                  materialIndex 3
                }
              }
              Shape {
                appearance USE rampbase_app
                geometry Mesh {
                  url [
                    "RampStairsSeesaw_Seesaw.dae"
                  ]
                  materialIndex 2
                }
              }
              Shape {
                appearance USE rampline_app
                geometry Mesh {
                  url [
                    "RampStairsSeesaw_Seesaw.dae"
                  ]
                  materialIndex 0
                }
              }
              Pose {
                translation 0.8 0.531 0.454
                children [
                  Shape {
                    appearance PBRAppearance {
                      baseColor IS ballColor
                      metalness 0.1
                    }
                    geometry Sphere {
                      radius 0.022
                    }
                  }
                ]
              }
            ]
            boundingObject Pose {
              translation 0.6 0.53 0.425
              children [
                Box {
                  size 2 0.4 0.02
                }
              ]
            }
            physics Physics {
            }
          }
        }
        Shape {
          appearance USE rampbase_app
          geometry Mesh {
            url [
              "RampStairsSeesaw_Seesaw.dae"
            ]
            materialIndex 1
          }
        }
      ]
      name "seesaw"
      boundingObject Pose {
        translation 0.6 0.72 -0.147989
        rotation 0 1 0 -0.785395307179586
        children [
          Box {
            size 0.8 0.02 0.8
          }
        ]
      }
    }
    Pose {
      translation -0.2 -0.2 0.572
      children [
        Shape {
          appearance PBRAppearance {
            baseColor IS ballColor
            metalness 0.1
          }
          geometry Sphere {
            radius 0.022
          }
        }
      ]
    }
  ]
  boundingObject Group {
    children [
      Pose {
        translation 0.21 -0.6 0.22
        children [
          Box {
            size 0.42 0.6 0.44
          }
        ]
      }
      Pose {
        translation -0.68 1.7591 0.006249
        rotation 1 0 0 -0.151599
        children [
          Box {
            size 0.6 3.64177 0.543691
          }
        ]
      }
      Pose {
        translation 0.983708 -1.2 0.017403
        rotation 0 1 0 0.256144521
        children [
          Box {
            size 2.17083 0.6 0.532055
          }
        ]
      }
      Pose {
        translation 0.63 -0.6 0.165
        children [
          Box {
            size 0.42 0.6 0.33
          }
        ]
      }
      Pose {
        translation 1.05 -0.6 0.11
        children [
          Box {
            size 0.42 0.6 0.22
          }
        ]
      }
      Pose {
        translation 1.47 -0.6 0.055
        children [
          Box {
            size 0.42 0.6 0.11
          }
        ]
      }
      Pose {
        translation -0.49 -0.75 0.275
        children [
          Box {
            size 0.98 1.5 0.55
          }
        ]
      }
    ]
  }
}
}